Workbook

Sheet HKSE_00823
A4: Key Statistics
A5: Price (HK$) | B5: 68.4
A6: Market Cap (HK$ Million) | B6: 142476.96
A7: Shares Outstanding (HK$ Million) | B7: 2090.64
A8: PE Ratio | B8: 119.56
A9: PB Ratio | B9: 0.89
A10: PS Ratio | B10: 13.11
A12: Growth Rates
A13: Annual Rates (per share) | B13: 10 yrs | C13: 5 yrs | D13: 12 months
A14: Revenue Growth (%) | B14: 8.5 | C14: 6.4 | D14: 1.7
A15: EBITDA Growth (%) | B15: 0 | C15: 0 | D15: 0
A16: Free Cash Flow Growth (%) | B16: 8 | C16: 4.9 | D16: 18.9
A17: Book Value Growth (%) | B17: 13.7 | C17: 6.5 | D17: -1.8
A20: Fiscal Period | B20: Mar2011 | C20: Mar2012 | D20: Mar2013 | E20: Mar2014 | F20: Mar2015 | G20: Mar2016 | H20: Mar2017 | I20: Mar2018 | J20: Mar2019 | K20: Mar2020 | L20: Mar2021 | M20: TTM/current | O20: Mar1983 | P20: Jun1983 | Q20: Sep1983 | R20: Dec1983 | S20: Mar1984 | T20: Jun1984 | U20: Sep1984 | V20: Dec1984 | W20: Mar1985 | X20: Jun1985 | Y20: Sep1985 | Z20: Dec1985 | AA20: Mar1986 | AB20: Jun1986 | AC20: Sep1986 | AD20: Dec1986 | AE20: Mar1987 | AF20: Jun1987 | AG20: Sep1987 | AH20: Dec1987 | AI20: Mar1988 | AJ20: Jun1988 | AK20: Sep1988 | AL20: Dec1988 | AM20: Mar1989 | AN20: Jun1989 | AO20: Sep1989 | AP20: Dec1989 | AQ20: Mar1990 | AR20: Jun1990 | AS20: Sep1990 | AT20: Dec1990 | AU20: Mar1991 | AV20: Jun1991 | AW20: Sep1991 | AX20: Dec1991 | AY20: Mar1992 | AZ20: Jun1992 | BA20: Sep1992 | BB20: Dec1992 | BC20: Mar1993 | BD20: Jun1993 | BE20: Sep1993 | BF20: Dec1993 | BG20: Mar1994 | BH20: Jun1994 | BI20: Sep1994 | BJ20: Dec1994 | BK20: Mar1995 | BL20: Jun1995 | BM20: Sep1995 | BN20: Dec1995 | BO20: Mar1996 | BP20: Jun1996 | BQ20: Sep1996 | BR20: Dec1996 | BS20: Mar1997 | BT20: Jun1997 | BU20: Sep1997 | BV20: Dec1997 | BW20: Mar1998 | BX20: Jun1998 | BY20: Sep1998 | BZ20: Dec1998 | CA20: Mar1999 | CB20: Jun1999 | CC20: Sep1999 | CD20: Dec1999 | CE20: Mar2000 | CF20: Jun2000 | CG20: Sep2000 | CH20: Dec2000 | CI20: Mar2001 | CJ20: Jun2001 | CK20: Sep2001 | CL20: Dec2001 | CM20: Mar2002 | CN20: Jun2002 | CO20: Sep2002 | CP20: Dec2002 | CQ20: Mar2003 | CR20: Jun2003 | CS20: Sep2003 | CT20: Dec2003 | CU20: Mar2004 | CV20: Jun2004 | CW20: Sep2004 | CX20: Dec2004 | CY20: Mar2005 | CZ20: Jun2005 | DA20: Sep2005 | DB20: Dec2005 | DC20: Mar2006 | DD20: Mar2007 | DE20: Mar2008 | DF20: Mar2009 | DG20: Sep2009 | DH20: Mar2010 | DI20: Sep2010 | DJ20: Mar2011 | DK20: Sep2011 | DL20: Mar2012 | DM20: Sep2012 | DN20: Mar2013 | DO20: Sep2013 | DP20: Mar2014 | DQ20: Sep2014 | DR20: Mar2015 | DS20: Sep2015 | DT20: Mar2016 | DU20: Sep2016 | DV20: Mar2017 | DW20: Sep2017 | DX20: Mar2018 | DY20: Sep2018 | DZ20: Mar2019 | EA20: Sep2019 | EB20: Mar2020 | EC20: Sep2020 | ED20: Mar2021
A21: Revenue per Share | B21: 2.414 | C21: 2.637 | D21: 2.852 | E21: 3.104 | F21: 3.353 | G21: 3.851 | H21: 4.142 | I21: 4.553 | J21: 4.72 | K21: 5.113 | L21: 5.198 | M21: 5.198 | O21: - | P21: - | Q21: - | R21: - | S21: - | T21: - | U21: - | V21: - | W21: - | X21: - | Y21: - | Z21: - | AA21: - | AB21: - | AC21: - | AD21: - | AE21: - | AF21: - | AG21: - | AH21: - | AI21: - | AJ21: - | AK21: - | AL21: - | AM21: - | AN21: - | AO21: - | AP21: - | AQ21: - | AR21: - | AS21: - | AT21: - | AU21: - | AV21: - | AW21: - | AX21: - | AY21: - | AZ21: - | BA21: - | BB21: - | BC21: - | BD21: - | BE21: - | BF21: - | BG21: - | BH21: - | BI21: - | BJ21: - | BK21: - | BL21: - | BM21: - | BN21: - | BO21: - | BP21: - | BQ21: - | BR21: - | BS21: - | BT21: - | BU21: - | BV21: - | BW21: - | BX21: - | BY21: - | BZ21: - | CA21: - | CB21: - | CC21: - | CD21: - | CE21: - | CF21: - | CG21: - | CH21: - | CI21: - | CJ21: - | CK21: - | CL21: - | CM21: - | CN21: - | CO21: - | CP21: - | CQ21: - | CR21: - | CS21: - | CT21: - | CU21: - | CV21: - | CW21: - | CX21: - | CY21: - | CZ21: - | DA21: - | DB21: - | DC21: 0 | DD21: 0 | DE21: 0 | DF21: 0 | DG21: 1.122 | DH21: 1.166 | DI21: 1.186 | DJ21: 1.227 | DK21: 1.288 | DL21: 1.348 | DM21: 1.407 | DN21: 1.445 | DO21: 1.52 | DP21: 1.583 | DQ21: 1.657 | DR21: 1.696 | DS21: 1.831 | DT21: 2.022 | DU21: 2.053 | DV21: 2.09 | DW21: 2.236 | DX21: 2.317 | DY21: 2.302 | DZ21: 2.419 | EA21: 2.485 | EB21: 2.585 | EC21: 2.539 | ED21: 2.659
A22: EBITDA per Share | B22: 7.354 | C22: 4.657 | D22: 9.668 | E22: 7.981 | F22: 12.336 | G22: 7.81 | H22: 8.665 | I22: 22.652 | J22: 10.468 | K22: -7.457 | L22: 1.344 | M22: 1.288 | O22: - | P22: - | Q22: - | R22: - | S22: - | T22: - | U22: - | V22: - | W22: - | X22: - | Y22: - | Z22: - | AA22: - | AB22: - | AC22: - | AD22: - | AE22: - | AF22: - | AG22: - | AH22: - | AI22: - | AJ22: - | AK22: - | AL22: - | AM22: - | AN22: - | AO22: - | AP22: - | AQ22: - | AR22: - | AS22: - | AT22: - | AU22: - | AV22: - | AW22: - | AX22: - | AY22: - | AZ22: - | BA22: - | BB22: - | BC22: - | BD22: - | BE22: - | BF22: - | BG22: - | BH22: - | BI22: - | BJ22: - | BK22: - | BL22: - | BM22: - | BN22: - | BO22: - | BP22: - | BQ22: - | BR22: - | BS22: - | BT22: - | BU22: - | BV22: - | BW22: - | BX22: - | BY22: - | BZ22: - | CA22: - | CB22: - | CC22: - | CD22: - | CE22: - | CF22: - | CG22: - | CH22: - | CI22: - | CJ22: - | CK22: - | CL22: - | CM22: - | CN22: - | CO22: - | CP22: - | CQ22: - | CR22: - | CS22: - | CT22: - | CU22: - | CV22: - | CW22: - | CX22: - | CY22: - | CZ22: - | DA22: - | DB22: - | DC22: 0 | DD22: 0 | DE22: 0 | DF22: 0 | DG22: 2.539 | DH22: 3.428 | DI22: 2.238 | DJ22: 5.095 | DK22: 2.311 | DL22: 2.335 | DM22: 3.915 | DN22: 5.734 | DO22: 3.312 | DP22: 4.656 | DQ22: 7.615 | DR22: 4.701 | DS22: 3.799 | DT22: 4.003 | DU22: 3.009 | DV22: 5.656 | DW22: 5.838 | DX22: 16.862 | DY22: 4.807 | DZ22: 5.657 | EA22: 3.642 | EB22: -11.287 | EC22: -1.623 | ED22: 2.911
A23: EBIT per Share | B23: 7.344 | C23: 4.646 | D23: 9.656 | E23: 7.972 | F23: 12.326 | G23: 7.8 | H23: 8.653 | I23: 22.643 | J23: 10.458 | K23: -7.492 | L23: 1.3 | M23: 1.288 | O23: - | P23: - | Q23: - | R23: - | S23: - | T23: - | U23: - | V23: - | W23: - | X23: - | Y23: - | Z23: - | AA23: - | AB23: - | AC23: - | AD23: - | AE23: - | AF23: - | AG23: - | AH23: - | AI23: - | AJ23: - | AK23: - | AL23: - | AM23: - | AN23: - | AO23: - | AP23: - | AQ23: - | AR23: - | AS23: - | AT23: - | AU23: - | AV23: - | AW23: - | AX23: - | AY23: - | AZ23: - | BA23: - | BB23: - | BC23: - | BD23: - | BE23: - | BF23: - | BG23: - | BH23: - | BI23: - | BJ23: - | BK23: - | BL23: - | BM23: - | BN23: - | BO23: - | BP23: - | BQ23: - | BR23: - | BS23: - | BT23: - | BU23: - | BV23: - | BW23: - | BX23: - | BY23: - | BZ23: - | CA23: - | CB23: - | CC23: - | CD23: - | CE23: - | CF23: - | CG23: - | CH23: - | CI23: - | CJ23: - | CK23: - | CL23: - | CM23: - | CN23: - | CO23: - | CP23: - | CQ23: - | CR23: - | CS23: - | CT23: - | CU23: - | CV23: - | CW23: - | CX23: - | CY23: - | CZ23: - | DA23: - | DB23: - | DC23: 0 | DD23: 0 | DE23: 0 | DF23: 0 | DG23: 2.539 | DH23: 3.428 | DI23: 2.238 | DJ23: 5.095 | DK23: 2.311 | DL23: 2.335 | DM23: 3.915 | DN23: 5.734 | DO23: 3.312 | DP23: 4.656 | DQ23: 7.615 | DR23: 4.701 | DS23: 3.799 | DT23: 4.003 | DU23: 3.009 | DV23: 5.656 | DW23: 5.838 | DX23: 16.862 | DY23: 4.807 | DZ23: 5.657 | EA23: 3.642 | EB23: -11.287 | EC23: -1.623 | ED23: 2.911
A24: Earnings per Share (Diluted) | B24: 6.89 | C24: 4.27 | D24: 9.23 | E24: 7.51 | F24: 11.82 | G24: 7.19 | H24: 7.93 | I24: 21.69 | J24: 9.56 | K24: -8.17 | L24: 0.57 | M24: 0.57 | O24: - | P24: - | Q24: - | R24: - | S24: - | T24: - | U24: - | V24: - | W24: - | X24: - | Y24: - | Z24: - | AA24: - | AB24: - | AC24: - | AD24: - | AE24: - | AF24: - | AG24: - | AH24: - | AI24: - | AJ24: - | AK24: - | AL24: - | AM24: - | AN24: - | AO24: - | AP24: - | AQ24: - | AR24: - | AS24: - | AT24: - | AU24: - | AV24: - | AW24: - | AX24: - | AY24: - | AZ24: - | BA24: - | BB24: - | BC24: - | BD24: - | BE24: - | BF24: - | BG24: - | BH24: - | BI24: - | BJ24: - | BK24: - | BL24: - | BM24: - | BN24: - | BO24: - | BP24: - | BQ24: - | BR24: - | BS24: - | BT24: - | BU24: - | BV24: - | BW24: - | BX24: - | BY24: - | BZ24: - | CA24: - | CB24: - | CC24: - | CD24: - | CE24: - | CF24: - | CG24: - | CH24: - | CI24: - | CJ24: - | CK24: - | CL24: - | CM24: - | CN24: - | CO24: - | CP24: - | CQ24: - | CR24: - | CS24: - | CT24: - | CU24: - | CV24: - | CW24: - | CX24: - | CY24: - | CZ24: - | DA24: - | DB24: - | DC24: 0 | DD24: 0 | DE24: 0 | DF24: 0 | DG24: 2.016 | DH24: 3.474 | DI24: 2.01 | DJ24: 4.88 | DK24: 2.09 | DL24: 2.17 | DM24: 3.7 | DN24: 5.53 | DO24: 3.08 | DP24: 4.43 | DQ24: 7.37 | DR24: 4.45 | DS24: 3.5 | DT24: 3.68 | DU24: 2.65 | DV24: 5.28 | DW24: 5.48 | DX24: 16.21 | DY24: 4.31 | DZ24: 5.25 | EA24: 3.14 | EB24: -11.37 | EC24: -1.99 | ED24: 2.56
A25: EPS without NRI | B25: 6.89 | C25: 4.27 | D25: 9.23 | E25: 7.51 | F25: 11.82 | G25: 7.19 | H25: 7.93 | I25: 21.69 | J25: 9.56 | K25: -8.17 | L25: 0.57 | M25: 0.57 | O25: - | P25: - | Q25: - | R25: - | S25: - | T25: - | U25: - | V25: - | W25: - | X25: - | Y25: - | Z25: - | AA25: - | AB25: - | AC25: - | AD25: - | AE25: - | AF25: - | AG25: - | AH25: - | AI25: - | AJ25: - | AK25: - | AL25: - | AM25: - | AN25: - | AO25: - | AP25: - | AQ25: - | AR25: - | AS25: - | AT25: - | AU25: - | AV25: - | AW25: - | AX25: - | AY25: - | AZ25: - | BA25: - | BB25: - | BC25: - | BD25: - | BE25: - | BF25: - | BG25: - | BH25: - | BI25: - | BJ25: - | BK25: - | BL25: - | BM25: - | BN25: - | BO25: - | BP25: - | BQ25: - | BR25: - | BS25: - | BT25: - | BU25: - | BV25: - | BW25: - | BX25: - | BY25: - | BZ25: - | CA25: - | CB25: - | CC25: - | CD25: - | CE25: - | CF25: - | CG25: - | CH25: - | CI25: - | CJ25: - | CK25: - | CL25: - | CM25: - | CN25: - | CO25: - | CP25: - | CQ25: - | CR25: - | CS25: - | CT25: - | CU25: - | CV25: - | CW25: - | CX25: - | CY25: - | CZ25: - | DA25: - | DB25: - | DC25: 0 | DD25: 0 | DE25: 0 | DF25: 0 | DG25: 2.016 | DH25: 3.474 | DI25: 2.01 | DJ25: 4.88 | DK25: 2.09 | DL25: 2.17 | DM25: 3.7 | DN25: 5.53 | DO25: 3.08 | DP25: 4.43 | DQ25: 7.37 | DR25: 4.45 | DS25: 3.5 | DT25: 3.68 | DU25: 2.65 | DV25: 5.28 | DW25: 5.48 | DX25: 16.21 | DY25: 4.31 | DZ25: 5.25 | EA25: 3.14 | EB25: -11.37 | EC25: -1.99 | ED25: 2.56
A26: Owner Earnings per Share (TTM) | B26: 6.756 | C26: 4.137 | D26: 9.138 | E26: 7.487 | F26: 11.857 | G26: 7.266 | H26: 7.978 | I26: 21.671 | J26: 9.38 | K26: -8.337 | L26: 0.337 | M26: 0.34 | O26: - | P26: - | Q26: - | R26: - | S26: - | T26: - | U26: - | V26: - | W26: - | X26: - | Y26: - | Z26: - | AA26: - | AB26: - | AC26: - | AD26: - | AE26: - | AF26: - | AG26: - | AH26: - | AI26: - | AJ26: - | AK26: - | AL26: - | AM26: - | AN26: - | AO26: - | AP26: - | AQ26: - | AR26: - | AS26: - | AT26: - | AU26: - | AV26: - | AW26: - | AX26: - | AY26: - | AZ26: - | BA26: - | BB26: - | BC26: - | BD26: - | BE26: - | BF26: - | BG26: - | BH26: - | BI26: - | BJ26: - | BK26: - | BL26: - | BM26: - | BN26: - | BO26: - | BP26: - | BQ26: - | BR26: - | BS26: - | BT26: - | BU26: - | BV26: - | BW26: - | BX26: - | BY26: - | BZ26: - | CA26: - | CB26: - | CC26: - | CD26: - | CE26: - | CF26: - | CG26: - | CH26: - | CI26: - | CJ26: - | CK26: - | CL26: - | CM26: - | CN26: - | CO26: - | CP26: - | CQ26: - | CR26: - | CS26: - | CT26: - | CU26: - | CV26: - | CW26: - | CX26: - | CY26: - | CZ26: - | DA26: - | DB26: - | DC26: 0 | DD26: 0 | DE26: 0 | DF26: 0 | DG26: 0 | DH26: 5.26 | DI26: 0 | DJ26: 6.756 | DK26: 0 | DL26: 4.137 | DM26: 0 | DN26: 9.138 | DO26: 0 | DP26: 7.487 | DQ26: 0 | DR26: 11.857 | DS26: 0 | DT26: 7.266 | DU26: 0 | DV26: 7.978 | DW26: 0 | DX26: 21.671 | DY26: 0 | DZ26: 9.38 | EA26: 0 | EB26: -8.337 | EC26: 0 | ED26: 0.337
A27: Free Cash Flow per Share | B27: 1.51 | C27: 1.664 | D27: 1.83 | E27: 2.013 | F27: 2.096 | G27: 2.496 | H27: 2.702 | I27: 2.928 | J27: 2.771 | K27: 2.865 | L27: 3.407 | M27: 3.406 | O27: - | P27: - | Q27: - | R27: - | S27: - | T27: - | U27: - | V27: - | W27: - | X27: - | Y27: - | Z27: - | AA27: - | AB27: - | AC27: - | AD27: - | AE27: - | AF27: - | AG27: - | AH27: - | AI27: - | AJ27: - | AK27: - | AL27: - | AM27: - | AN27: - | AO27: - | AP27: - | AQ27: - | AR27: - | AS27: - | AT27: - | AU27: - | AV27: - | AW27: - | AX27: - | AY27: - | AZ27: - | BA27: - | BB27: - | BC27: - | BD27: - | BE27: - | BF27: - | BG27: - | BH27: - | BI27: - | BJ27: - | BK27: - | BL27: - | BM27: - | BN27: - | BO27: - | BP27: - | BQ27: - | BR27: - | BS27: - | BT27: - | BU27: - | BV27: - | BW27: - | BX27: - | BY27: - | BZ27: - | CA27: - | CB27: - | CC27: - | CD27: - | CE27: - | CF27: - | CG27: - | CH27: - | CI27: - | CJ27: - | CK27: - | CL27: - | CM27: - | CN27: - | CO27: - | CP27: - | CQ27: - | CR27: - | CS27: - | CT27: - | CU27: - | CV27: - | CW27: - | CX27: - | CY27: - | CZ27: - | DA27: - | DB27: - | DC27: 0 | DD27: 0 | DE27: 0 | DF27: 0 | DG27: 0.498 | DH27: 0.53 | DI27: 0.601 | DJ27: 0.908 | DK27: 0.821 | DL27: 0.843 | DM27: 0.925 | DN27: 0.904 | DO27: 1.01 | DP27: 1.003 | DQ27: 1.093 | DR27: 1.002 | DS27: 1.24 | DT27: 1.256 | DU27: 1.395 | DV27: 1.307 | DW27: 1.528 | DX27: 1.399 | DY27: 1.315 | DZ27: 1.457 | EA27: 1.457 | EB27: 1.383 | EC27: 1.527 | ED27: 1.879
A28: Operating Cash Flow per Share | B28: 1.518 | C28: 1.676 | D28: 1.841 | E28: 2.021 | F28: 2.107 | G28: 2.504 | H28: 2.72 | I28: 2.946 | J28: 2.794 | K28: 3.143 | L28: 3.424 | M28: 3.423 | O28: - | P28: - | Q28: - | R28: - | S28: - | T28: - | U28: - | V28: - | W28: - | X28: - | Y28: - | Z28: - | AA28: - | AB28: - | AC28: - | AD28: - | AE28: - | AF28: - | AG28: - | AH28: - | AI28: - | AJ28: - | AK28: - | AL28: - | AM28: - | AN28: - | AO28: - | AP28: - | AQ28: - | AR28: - | AS28: - | AT28: - | AU28: - | AV28: - | AW28: - | AX28: - | AY28: - | AZ28: - | BA28: - | BB28: - | BC28: - | BD28: - | BE28: - | BF28: - | BG28: - | BH28: - | BI28: - | BJ28: - | BK28: - | BL28: - | BM28: - | BN28: - | BO28: - | BP28: - | BQ28: - | BR28: - | BS28: - | BT28: - | BU28: - | BV28: - | BW28: - | BX28: - | BY28: - | BZ28: - | CA28: - | CB28: - | CC28: - | CD28: - | CE28: - | CF28: - | CG28: - | CH28: - | CI28: - | CJ28: - | CK28: - | CL28: - | CM28: - | CN28: - | CO28: - | CP28: - | CQ28: - | CR28: - | CS28: - | CT28: - | CU28: - | CV28: - | CW28: - | CX28: - | CY28: - | CZ28: - | DA28: - | DB28: - | DC28: 0 | DD28: 0 | DE28: 0 | DF28: 0 | DG28: 0.67 | DH28: 0.704 | DI28: 0.736 | DJ28: 0.781 | DK28: 0.825 | DL28: 0.851 | DM28: 0.931 | DN28: 0.91 | DO28: 1.013 | DP28: 1.008 | DQ28: 1.1 | DR28: 1.007 | DS28: 1.242 | DT28: 1.262 | DU28: 1.403 | DV28: 1.316 | DW28: 1.535 | DX28: 1.41 | DY28: 1.323 | DZ28: 1.472 | EA28: 1.547 | EB28: 1.57 | EC28: 1.536 | ED28: 1.887
A29: FFO per Share | B29: 6.902 | C29: 1.31 | D29: 1.485 | E29: 1.683 | F29: 1.785 | G29: 2.052 | H29: 2.174 | I29: 2.263 | J29: 2.502 | K29: 3.299 | L29: 3.202 | M29: 0.352 | O29: - | P29: - | Q29: - | R29: - | S29: - | T29: - | U29: - | V29: - | W29: - | X29: - | Y29: - | Z29: - | AA29: - | AB29: - | AC29: - | AD29: - | AE29: - | AF29: - | AG29: - | AH29: - | AI29: - | AJ29: - | AK29: - | AL29: - | AM29: - | AN29: - | AO29: - | AP29: - | AQ29: - | AR29: - | AS29: - | AT29: - | AU29: - | AV29: - | AW29: - | AX29: - | AY29: - | AZ29: - | BA29: - | BB29: - | BC29: - | BD29: - | BE29: - | BF29: - | BG29: - | BH29: - | BI29: - | BJ29: - | BK29: - | BL29: - | BM29: - | BN29: - | BO29: - | BP29: - | BQ29: - | BR29: - | BS29: - | BT29: - | BU29: - | BV29: - | BW29: - | BX29: - | BY29: - | BZ29: - | CA29: - | CB29: - | CC29: - | CD29: - | CE29: - | CF29: - | CG29: - | CH29: - | CI29: - | CJ29: - | CK29: - | CL29: - | CM29: - | CN29: - | CO29: - | CP29: - | CQ29: - | CR29: - | CS29: - | CT29: - | CU29: - | CV29: - | CW29: - | CX29: - | CY29: - | CZ29: - | DA29: - | DB29: - | DC29: 0 | DD29: 0 | DE29: 0 | DF29: 0 | DG29: 2.016 | DH29: 3.472 | DI29: 2.008 | DJ29: 4.871 | DK29: 2.094 | DL29: 2.174 | DM29: 3.704 | DN29: 5.523 | DO29: 3.08 | DP29: 4.422 | DQ29: 7.368 | DR29: 4.442 | DS29: 3.517 | DT29: 3.688 | DU29: 2.698 | DV29: 5.331 | DW29: 5.485 | DX29: 16.365 | DY29: 4.36 | DZ29: 5.26 | EA29: 3.131 | EB29: -11.528 | EC29: -2.098 | ED29: 2.45
A30: Cash per Share | B30: 0.383 | C30: 0.757 | D30: 1.378 | E30: 1.209 | F30: 1.505 | G30: 0.202 | H30: 0.31 | I30: 5.437 | J30: 3.219 | K30: 3.828 | L30: 1.215 | M30: 1.215 | O30: - | P30: - | Q30: - | R30: - | S30: - | T30: - | U30: - | V30: - | W30: - | X30: - | Y30: - | Z30: - | AA30: - | AB30: - | AC30: - | AD30: - | AE30: - | AF30: - | AG30: - | AH30: - | AI30: - | AJ30: - | AK30: - | AL30: - | AM30: - | AN30: - | AO30: - | AP30: - | AQ30: - | AR30: - | AS30: - | AT30: - | AU30: - | AV30: - | AW30: - | AX30: - | AY30: - | AZ30: - | BA30: - | BB30: - | BC30: - | BD30: - | BE30: - | BF30: - | BG30: - | BH30: - | BI30: - | BJ30: - | BK30: - | BL30: - | BM30: - | BN30: - | BO30: - | BP30: - | BQ30: - | BR30: - | BS30: - | BT30: - | BU30: - | BV30: - | BW30: - | BX30: - | BY30: - | BZ30: - | CA30: - | CB30: - | CC30: - | CD30: - | CE30: - | CF30: - | CG30: - | CH30: - | CI30: - | CJ30: - | CK30: - | CL30: - | CM30: - | CN30: - | CO30: - | CP30: - | CQ30: - | CR30: - | CS30: - | CT30: - | CU30: - | CV30: - | CW30: - | CX30: - | CY30: - | CZ30: - | DA30: - | DB30: - | DC30: 0.35 | DD30: 0.698 | DE30: 0.845 | DF30: 0.554 | DG30: 0 | DH30: 0.388 | DI30: 0.409 | DJ30: 0.383 | DK30: 0.95 | DL30: 0.757 | DM30: 1.19 | DN30: 1.378 | DO30: 1.105 | DP30: 1.209 | DQ30: 1.562 | DR30: 1.505 | DS30: 0.23 | DT30: 0.202 | DU30: 0.226 | DV30: 0.31 | DW30: 0.28 | DX30: 5.437 | DY30: 1.823 | DZ30: 3.219 | EA30: 2.982 | EB30: 3.828 | EC30: 0.88 | ED30: 1.215
A31: Dividends per Share | B31: 1.00692 | C31: 1.207 | D31: 1.3749 | E31: 1.556 | F31: 1.7515 | G31: 1.9227 | H31: 2.1894 | I31: 2.3816 | J31: 2.589 | K31: 2.8202 | L31: 2.8737 | M31: 2.8737 | O31: - | P31: - | Q31: - | R31: - | S31: - | T31: - | U31: - | V31: - | W31: - | X31: - | Y31: - | Z31: - | AA31: - | AB31: - | AC31: - | AD31: - | AE31: - | AF31: - | AG31: - | AH31: - | AI31: - | AJ31: - | AK31: - | AL31: - | AM31: - | AN31: - | AO31: - | AP31: - | AQ31: - | AR31: - | AS31: - | AT31: - | AU31: - | AV31: - | AW31: - | AX31: - | AY31: - | AZ31: - | BA31: - | BB31: - | BC31: - | BD31: - | BE31: - | BF31: - | BG31: - | BH31: - | BI31: - | BJ31: - | BK31: - | BL31: - | BM31: - | BN31: - | BO31: - | BP31: - | BQ31: - | BR31: - | BS31: - | BT31: - | BU31: - | BV31: - | BW31: - | BX31: - | BY31: - | BZ31: - | CA31: - | CB31: - | CC31: - | CD31: - | CE31: - | CF31: - | CG31: - | CH31: - | CI31: - | CJ31: - | CK31: - | CL31: - | CM31: - | CN31: - | CO31: - | CP31: - | CQ31: - | CR31: - | CS31: - | CT31: - | CU31: - | CV31: - | CW31: - | CX31: - | CY31: - | CZ31: - | DA31: - | DB31: - | DC31: 0 | DD31: 0 | DE31: 0 | DF31: 0 | DG31: 0.42085 | DH31: 0.471786 | DI31: 0.478323 | DJ31: 0.5286 | DK31: 0.5759 | DL31: 0.6311 | DM31: 0.6641 | DN31: 0.7108 | DO31: 0.7538 | DP31: 0.8022 | DQ31: 0.8559 | DR31: 0.8956 | DS31: 0.9328 | DT31: 0.9899 | DU31: 1.0719 | DV31: 1.1175 | DW31: 1.1666 | DX31: 1.215 | DY31: 1.2828 | DZ31: 1.3062 | EA31: 1.4055 | EB31: 1.4147 | EC31: 1.4572 | ED31: 1.4165
A32: Book Value per Share | B32: 24.627 | C32: 27.73 | D32: 35.682 | E32: 41.694 | F32: 51.535 | G32: 56.789 | H32: 62.468 | I32: 83.065 | J32: 89.479 | K32: 77.609 | L32: 76.24 | M32: 76.24 | O32: - | P32: - | Q32: - | R32: - | S32: - | T32: - | U32: - | V32: - | W32: - | X32: - | Y32: - | Z32: - | AA32: - | AB32: - | AC32: - | AD32: - | AE32: - | AF32: - | AG32: - | AH32: - | AI32: - | AJ32: - | AK32: - | AL32: - | AM32: - | AN32: - | AO32: - | AP32: - | AQ32: - | AR32: - | AS32: - | AT32: - | AU32: - | AV32: - | AW32: - | AX32: - | AY32: - | AZ32: - | BA32: - | BB32: - | BC32: - | BD32: - | BE32: - | BF32: - | BG32: - | BH32: - | BI32: - | BJ32: - | BK32: - | BL32: - | BM32: - | BN32: - | BO32: - | BP32: - | BQ32: - | BR32: - | BS32: - | BT32: - | BU32: - | BV32: - | BW32: - | BX32: - | BY32: - | BZ32: - | CA32: - | CB32: - | CC32: - | CD32: - | CE32: - | CF32: - | CG32: - | CH32: - | CI32: - | CJ32: - | CK32: - | CL32: - | CM32: - | CN32: - | CO32: - | CP32: - | CQ32: - | CR32: - | CS32: - | CT32: - | CU32: - | CV32: - | CW32: - | CX32: - | CY32: - | CZ32: - | DA32: - | DB32: - | DC32: 10.826 | DD32: 12.229 | DE32: 13.813 | DF32: 13.149 | DG32: 0 | DH32: 18.232 | DI32: 18.727 | DJ32: 24.627 | DK32: 26.142 | DL32: 27.73 | DM32: 30.815 | DN32: 35.682 | DO32: 38.042 | DP32: 41.694 | DQ32: 48.233 | DR32: 51.535 | DS32: 54.236 | DT32: 56.789 | DU32: 58.203 | DV32: 62.468 | DW32: 67.11 | DX32: 83.065 | DY32: 85.407 | DZ32: 89.479 | EA32: 90.58 | EB32: 77.609 | EC32: 74.598 | ED32: 76.24
... A49: FCF Margin % | B49: 62.56 | C49: 63.1 | D49: 64.16 | E49: 64.86 | F49: 62.51 | G49: 64.81 | H49: 65.24 | I49: 64.31 | J49: 58.7 | K49: 56.04 | L49: 65.53 | M49: 65.53 | O49: - | P49: - | Q49: - | R49: - | S49: - | T49: - | U49: - | V49: - | W49: - | X49: - | Y49: - | Z49: - | AA49: - | AB49: - | AC49: - | AD49: - | AE49: - | AF49: - | AG49: - | AH49: - | AI49: - | AJ49: - | AK49: - | AL49: - | AM49: - | AN49: - | AO49: - | AP49: - | AQ49: - | AR49: - | AS49: - | AT49: - | AU49: - | AV49: - | AW49: - | AX49: - | AY49: - | AZ49: - | BA49: - | BB49: - | BC49: - | BD49: - | BE49: - | BF49: - | BG49: - | BH49: - | BI49: - | BJ49: - | BK49: - | BL49: - | BM49: - | BN49: - | BO49: - | BP49: - | BQ49: - | BR49: - | BS49: - | BT49: - | BU49: - | BV49: - | BW49: - | BX49: - | BY49: - | BZ49: - | CA49: - | CB49: - | CC49: - | CD49: - | CE49: - | CF49: - | CG49: - | CH49: - | CI49: - | CJ49: - | CK49: - | CL49: - | CM49: - | CN49: - | CO49: - | CP49: - | CQ49: - | CR49: - | CS49: - | CT49: - | CU49: - | CV49: - | CW49: - | CX49: - | CY49: - | CZ49: - | DA49: - | DB49: - | DC49: 0 | DD49: 0 | DE49: 0 | DF49: 0 | DG49: 44.38 | DH49: 45.45 | DI49: 50.63 | DJ49: 74.01 | DK49: 63.7 | DL49: 62.53 | DM49: 65.78 | DN49: 62.59 | DO49: 66.42 | DP49: 63.38 | DQ49: 65.98 | DR49: 59.11 | DS49: 67.72 | DT49: 62.13 | DU49: 67.95 | DV49: 62.56 | DW49: 68.32 | DX49: 60.41 | DY49: 57.12 | DZ49: 60.23 | EA49: 58.61 | EB49: 53.49 | EC49: 60.14 | ED49: 70.66
A50: Debt-to-Equity | B50: 0.189 | C50: 0.201 | D50: 0.166 | E50: 0.13 | F50: 0.145 | G50: 0.211 | H50: 0.199 | I50: 0.144 | J50: 0.128 | K50: 0.217 | L50: 0.243 | M50: 0.243 | O50: - | P50: - | Q50: - | R50: - | S50: - | T50: - | U50: - | V50: - | W50: - | X50: - | Y50: - | Z50: - | AA50: - | AB50: - | AC50: - | AD50: - | AE50: - | AF50: - | AG50: - | AH50: - | AI50: - | AJ50: - | AK50: - | AL50: - | AM50: - | AN50: - | AO50: - | AP50: - | AQ50: - | AR50: - | AS50: - | AT50: - | AU50: - | AV50: - | AW50: - | AX50: - | AY50: - | AZ50: - | BA50: - | BB50: - | BC50: - | BD50: - | BE50: - | BF50: - | BG50: - | BH50: - | BI50: - | BJ50: - | BK50: - | BL50: - | BM50: - | BN50: - | BO50: - | BP50: - | BQ50: - | BR50: - | BS50: - | BT50: - | BU50: - | BV50: - | BW50: - | BX50: - | BY50: - | BZ50: - | CA50: - | CB50: - | CC50: - | CD50: - | CE50: - | CF50: - | CG50: - | CH50: - | CI50: - | CJ50: - | CK50: - | CL50: - | CM50: - | CN50: - | CO50: - | CP50: - | CQ50: - | CR50: - | CS50: - | CT50: - | CU50: - | CV50: - | CW50: - | CX50: - | CY50: - | CZ50: - | DA50: - | DB50: - | DC50: 0.513 | DD50: 0.455 | DE50: 0.411 | DF50: 0.412 | DG50: - | DH50: 0.264 | DI50: 0.258 | DJ50: 0.189 | DK50: 0.213 | DL50: 0.201 | DM50: 0.185 | DN50: 0.166 | DO50: 0.137 | DP50: 0.13 | DQ50: 0.129 | DR50: 0.145 | DS50: 0.218 | DT50: 0.211 | DU50: 0.229 | DV50: 0.199 | DW50: 0.226 | DX50: 0.144 | DY50: 0.123 | DZ50: 0.128 | EA50: 0.146 | EB50: 0.217 | EC50: 0.234 | ED50: 0.243
A51: Equity-to-Asset | B51: 0.8 | C51: 0.792 | D51: 0.821 | E51: 0.849 | F51: 0.825 | G51: 0.779 | H51: 0.786 | I51: 0.825 | J51: 0.832 | K51: 0.769 | L51: 0.756 | M51: 0.756 | O51: - | P51: - | Q51: - | R51: - | S51: - | T51: - | U51: - | V51: - | W51: - | X51: - | Y51: - | Z51: - | AA51: - | AB51: - | AC51: - | AD51: - | AE51: - | AF51: - | AG51: - | AH51: - | AI51: - | AJ51: - | AK51: - | AL51: - | AM51: - | AN51: - | AO51: - | AP51: - | AQ51: - | AR51: - | AS51: - | AT51: - | AU51: - | AV51: - | AW51: - | AX51: - | AY51: - | AZ51: - | BA51: - | BB51: - | BC51: - | BD51: - | BE51: - | BF51: - | BG51: - | BH51: - | BI51: - | BJ51: - | BK51: - | BL51: - | BM51: - | BN51: - | BO51: - | BP51: - | BQ51: - | BR51: - | BS51: - | BT51: - | BU51: - | BV51: - | BW51: - | BX51: - | BY51: - | BZ51: - | CA51: - | CB51: - | CC51: - | CD51: - | CE51: - | CF51: - | CG51: - | CH51: - | CI51: - | CJ51: - | CK51: - | CL51: - | CM51: - | CN51: - | CO51: - | CP51: - | CQ51: - | CR51: - | CS51: - | CT51: - | CU51: - | CV51: - | CW51: - | CX51: - | CY51: - | CZ51: - | DA51: - | DB51: - | DC51: 0.583 | DD51: 0.592 | DE51: 0.607 | DF51: 0.6 | DG51: 0 | DH51: 0.745 | DI51: 0.664 | DJ51: 0.8 | DK51: 0.784 | DL51: 0.792 | DM51: 0.805 | DN51: 0.821 | DO51: 0.843 | DP51: 0.849 | DQ51: 0.851 | DR51: 0.825 | DS51: 0.776 | DT51: 0.779 | DU51: 0.767 | DV51: 0.786 | DW51: 0.77 | DX51: 0.825 | DY51: 0.838 | DZ51: 0.832 | EA51: 0.819 | EB51: 0.769 | EC51: 0.757 | ED51: 0.756
A52: Debt-to-Asset | B52: 0.151 | C52: 0.159 | D52: 0.136 | E52: 0.11 | F52: 0.119 | G52: 0.165 | H52: 0.156 | I52: 0.119 | J52: 0.107 | K52: 0.167 | L52: 0.184 | M52: 0.184 | O52: - | P52: - | Q52: - | R52: - | S52: - | T52: - | U52: - | V52: - | W52: - | X52: - | Y52: - | Z52: - | AA52: - | AB52: - | AC52: - | AD52: - | AE52: - | AF52: - | AG52: - | AH52: - | AI52: - | AJ52: - | AK52: - | AL52: - | AM52: - | AN52: - | AO52: - | AP52: - | AQ52: - | AR52: - | AS52: - | AT52: - | AU52: - | AV52: - | AW52: - | AX52: - | AY52: - | AZ52: - | BA52: - | BB52: - | BC52: - | BD52: - | BE52: - | BF52: - | BG52: - | BH52: - | BI52: - | BJ52: - | BK52: - | BL52: - | BM52: - | BN52: - | BO52: - | BP52: - | BQ52: - | BR52: - | BS52: - | BT52: - | BU52: - | BV52: - | BW52: - | BX52: - | BY52: - | BZ52: - | CA52: - | CB52: - | CC52: - | CD52: - | CE52: - | CF52: - | CG52: - | CH52: - | CI52: - | CJ52: - | CK52: - | CL52: - | CM52: - | CN52: - | CO52: - | CP52: - | CQ52: - | CR52: - | CS52: - | CT52: - | CU52: - | CV52: - | CW52: - | CX52: - | CY52: - | CZ52: - | DA52: - | DB52: - | DC52: 0.299 | DD52: 0.269 | DE52: 0.249 | DF52: 0.247 | DG52: 0 | DH52: 0.197 | DI52: 0.171 | DJ52: 0.151 | DK52: 0.167 | DL52: 0.159 | DM52: 0.149 | DN52: 0.136 | DO52: 0.116 | DP52: 0.11 | DQ52: 0.11 | DR52: 0.119 | DS52: 0.169 | DT52: 0.165 | DU52: 0.176 | DV52: 0.156 | DW52: 0.174 | DX52: 0.119 | DY52: 0.103 | DZ52: 0.107 | EA52: 0.12 | EB52: 0.167 | EC52: 0.177 | ED52: 0.184
A53: Liabilities-to-Assets | B53: 0.2 | C53: 0.208 | D53: 0.179 | E53: 0.151 | F53: 0.175 | G53: 0.22 | H53: 0.213 | I53: 0.173 | J53: 0.166 | K53: 0.229 | L53: 0.244 | M53: 0.244 | O53: - | P53: - | Q53: - | R53: - | S53: - | T53: - | U53: - | V53: - | W53: - | X53: - | Y53: - | Z53: - | AA53: - | AB53: - | AC53: - | AD53: - | AE53: - | AF53: - | AG53: - | AH53: - | AI53: - | AJ53: - | AK53: - | AL53: - | AM53: - | AN53: - | AO53: - | AP53: - | AQ53: - | AR53: - | AS53: - | AT53: - | AU53: - | AV53: - | AW53: - | AX53: - | AY53: - | AZ53: - | BA53: - | BB53: - | BC53: - | BD53: - | BE53: - | BF53: - | BG53: - | BH53: - | BI53: - | BJ53: - | BK53: - | BL53: - | BM53: - | BN53: - | BO53: - | BP53: - | BQ53: - | BR53: - | BS53: - | BT53: - | BU53: - | BV53: - | BW53: - | BX53: - | BY53: - | BZ53: - | CA53: - | CB53: - | CC53: - | CD53: - | CE53: - | CF53: - | CG53: - | CH53: - | CI53: - | CJ53: - | CK53: - | CL53: - | CM53: - | CN53: - | CO53: - | CP53: - | CQ53: - | CR53: - | CS53: - | CT53: - | CU53: - | CV53: - | CW53: - | CX53: - | CY53: - | CZ53: - | DA53: - | DB53: - | DC53: 0.417 | DD53: 0.408 | DE53: 0.393 | DF53: 0.4 | DG53: 0 | DH53: 0.255 | DI53: 0.336 | DJ53: 0.2 | DK53: 0.216 | DL53: 0.208 | DM53: 0.195 | DN53: 0.179 | DO53: 0.157 | DP53: 0.151 | DQ53: 0.149 | DR53: 0.175 | DS53: 0.224 | DT53: 0.22 | DU53: 0.232 | DV53: 0.213 | DW53: 0.229 | DX53: 0.173 | DY53: 0.159 | DZ53: 0.166 | EA53: 0.179 | EB53: 0.229 | EC53: 0.242 | ED53: 0.244
A54: Gross-Profit-to-Asset % | B54: 5.88 | C54: 5.66 | D54: 5.17 | E54: 4.89 | F54: 4.42 | G54: 4.25 | H54: 4.12 | I54: 3.91 | J54: 3.47 | K54: 3.78 | L54: 3.95 | M54: 3.98 | O54: - | P54: - | Q54: - | R54: - | S54: - | T54: - | U54: - | V54: - | W54: - | X54: - | Y54: - | Z54: - | AA54: - | AB54: - | AC54: - | AD54: - | AE54: - | AF54: - | AG54: - | AH54: - | AI54: - | AJ54: - | AK54: - | AL54: - | AM54: - | AN54: - | AO54: - | AP54: - | AQ54: - | AR54: - | AS54: - | AT54: - | AU54: - | AV54: - | AW54: - | AX54: - | AY54: - | AZ54: - | BA54: - | BB54: - | BC54: - | BD54: - | BE54: - | BF54: - | BG54: - | BH54: - | BI54: - | BJ54: - | BK54: - | BL54: - | BM54: - | BN54: - | BO54: - | BP54: - | BQ54: - | BR54: - | BS54: - | BT54: - | BU54: - | BV54: - | BW54: - | BX54: - | BY54: - | BZ54: - | CA54: - | CB54: - | CC54: - | CD54: - | CE54: - | CF54: - | CG54: - | CH54: - | CI54: - | CJ54: - | CK54: - | CL54: - | CM54: - | CN54: - | CO54: - | CP54: - | CQ54: - | CR54: - | CS54: - | CT54: - | CU54: - | CV54: - | CW54: - | CX54: - | CY54: - | CZ54: - | DA54: - | DB54: - | DC54: 0 | DD54: 0 | DE54: 0 | DF54: 0 | DG54: 6.64 | DH54: 6.2 | DI54: 5.99 | DJ54: 5.72 | DK54: 5.68 | DL54: 5.56 | DM54: 5.41 | DN54: 5.05 | DO54: 4.94 | DP54: 4.93 | DQ54: 4.57 | DR54: 4.23 | DS54: 4.12 | DT54: 4.26 | DU54: 4.14 | DV54: 4.12 | DW54: 4.1 | DX54: 3.82 | DY54: 3.48 | DZ54: 3.55 | EA54: 3.55 | EB54: 3.78 | EC54: 3.93 | ED54: 4.07
A55: Asset Turnover | B55: 0.086 | C55: 0.08 | D55: 0.073 | E55: 0.067 | F55: 0.06 | G55: 0.057 | H55: 0.055 | I55: 0.051 | J55: 0.045 | K55: 0.049 | L55: 0.051 | M55: 0.05 | O55: - | P55: - | Q55: - | R55: - | S55: - | T55: - | U55: - | V55: - | W55: - | X55: - | Y55: - | Z55: - | AA55: - | AB55: - | AC55: - | AD55: - | AE55: - | AF55: - | AG55: - | AH55: - | AI55: - | AJ55: - | AK55: - | AL55: - | AM55: - | AN55: - | AO55: - | AP55: - | AQ55: - | AR55: - | AS55: - | AT55: - | AU55: - | AV55: - | AW55: - | AX55: - | AY55: - | AZ55: - | BA55: - | BB55: - | BC55: - | BD55: - | BE55: - | BF55: - | BG55: - | BH55: - | BI55: - | BJ55: - | BK55: - | BL55: - | BM55: - | BN55: - | BO55: - | BP55: - | BQ55: - | BR55: - | BS55: - | BT55: - | BU55: - | BV55: - | BW55: - | BX55: - | BY55: - | BZ55: - | CA55: - | CB55: - | CC55: - | CD55: - | CE55: - | CF55: - | CG55: - | CH55: - | CI55: - | CJ55: - | CK55: - | CL55: - | CM55: - | CN55: - | CO55: - | CP55: - | CQ55: - | CR55: - | CS55: - | CT55: - | CU55: - | CV55: - | CW55: - | CX55: - | CY55: - | CZ55: - | DA55: - | DB55: - | DC55: 0 | DD55: 0 | DE55: 0 | DF55: 0 | DG55: 0.05 | DH55: 0.046 | DI55: 0.045 | DJ55: 0.042 | DK55: 0.04 | DL55: 0.039 | DM55: 0.038 | DN55: 0.035 | DO55: 0.034 | DP55: 0.034 | DQ55: 0.031 | DR55: 0.029 | DS55: 0.028 | DT55: 0.028 | DU55: 0.028 | DV55: 0.027 | DW55: 0.027 | DX55: 0.025 | DY55: 0.023 | DZ55: 0.023 | EA55: 0.023 | EB55: 0.025 | EC55: 0.025 | ED55: 0.027
A56: Dividend Payout Ratio | B56: 0.146 | C56: 0.283 | D56: 0.149 | E56: 0.207 | F56: 0.148 | G56: 0.267 | H56: 0.276 | I56: 0.11 | J56: 0.271 | K56: 0 | L56: 5.042 | M56: 5.04 | O56: - | P56: - | Q56: - | R56: - | S56: - | T56: - | U56: - | V56: - | W56: - | X56: - | Y56: - | Z56: - | AA56: - | AB56: - | AC56: - | AD56: - | AE56: - | AF56: - | AG56: - | AH56: - | AI56: - | AJ56: - | AK56: - | AL56: - | AM56: - | AN56: - | AO56: - | AP56: - | AQ56: - | AR56: - | AS56: - | AT56: - | AU56: - | AV56: - | AW56: - | AX56: - | AY56: - | AZ56: - | BA56: - | BB56: - | BC56: - | BD56: - | BE56: - | BF56: - | BG56: - | BH56: - | BI56: - | BJ56: - | BK56: - | BL56: - | BM56: - | BN56: - | BO56: - | BP56: - | BQ56: - | BR56: - | BS56: - | BT56: - | BU56: - | BV56: - | BW56: - | BX56: - | BY56: - | BZ56: - | CA56: - | CB56: - | CC56: - | CD56: - | CE56: - | CF56: - | CG56: - | CH56: - | CI56: - | CJ56: - | CK56: - | CL56: - | CM56: - | CN56: - | CO56: - | CP56: - | CQ56: - | CR56: - | CS56: - | CT56: - | CU56: - | CV56: - | CW56: - | CX56: - | CY56: - | CZ56: - | DA56: - | DB56: - | DC56: 0 | DD56: 0 | DE56: 0 | DF56: 0 | DG56: 0.209 | DH56: 0.136 | DI56: 0.238 | DJ56: 0.108 | DK56: 0.276 | DL56: 0.291 | DM56: 0.179 | DN56: 0.129 | DO56: 0.245 | DP56: 0.181 | DQ56: 0.116 | DR56: 0.201 | DS56: 0.267 | DT56: 0.269 | DU56: 0.404 | DV56: 0.212 | DW56: 0.213 | DX56: 0.075 | DY56: 0.298 | DZ56: 0.249 | EA56: 0.448 | EB56: 0 | EC56: 0 | ED56: 0.553
A57: Dividend-Payout-to-FFO | B57: 0.146 | C57: 0.921 | D57: 0.926 | E57: 0.925 | F57: 0.981 | G57: 0.937 | H57: 1.007 | I57: 1.052 | J57: 1.035 | K57: 0.855 | L57: 0.897 | M57: 8.16 | O57: - | P57: - | Q57: - | R57: - | S57: - | T57: - | U57: - | V57: - | W57: - | X57: - | Y57: - | Z57: - | AA57: - | AB57: - | AC57: - | AD57: - | AE57: - | AF57: - | AG57: - | AH57: - | AI57: - | AJ57: - | AK57: - | AL57: - | AM57: - | AN57: - | AO57: - | AP57: - | AQ57: - | AR57: - | AS57: - | AT57: - | AU57: - | AV57: - | AW57: - | AX57: - | AY57: - | AZ57: - | BA57: - | BB57: - | BC57: - | BD57: - | BE57: - | BF57: - | BG57: - | BH57: - | BI57: - | BJ57: - | BK57: - | BL57: - | BM57: - | BN57: - | BO57: - | BP57: - | BQ57: - | BR57: - | BS57: - | BT57: - | BU57: - | BV57: - | BW57: - | BX57: - | BY57: - | BZ57: - | CA57: - | CB57: - | CC57: - | CD57: - | CE57: - | CF57: - | CG57: - | CH57: - | CI57: - | CJ57: - | CK57: - | CL57: - | CM57: - | CN57: - | CO57: - | CP57: - | CQ57: - | CR57: - | CS57: - | CT57: - | CU57: - | CV57: - | CW57: - | CX57: - | CY57: - | CZ57: - | DA57: - | DB57: - | DC57: 0 | DD57: 0 | DE57: 0 | DF57: 0 | DG57: 0.209 | DH57: 0.136 | DI57: 0.238 | DJ57: 0.109 | DK57: 0.275 | DL57: 0.29 | DM57: 0.179 | DN57: 0.129 | DO57: 0.245 | DP57: 0.181 | DQ57: 0.116 | DR57: 0.202 | DS57: 0.265 | DT57: 0.268 | DU57: 0.397 | DV57: 0.21 | DW57: 0.213 | DX57: 0.074 | DY57: 0.294 | DZ57: 0.248 | EA57: 0.449 | EB57: -0.123 | EC57: -0.695 | ED57: 0.578
A58: Days Sales Outstanding | B58: 0 | C58: 3.26 | D58: 3.48 | E58: 3.47 | F58: 3.78 | G58: 3.9 | H58: 3.35 | I58: 3.35 | J58: 3.95 | K58: 5.47 | L58: 7.86 | M58: 7.43 | O58: - | P58: - | Q58: - | R58: - | S58: - | T58: - | U58: - | V58: - | W58: - | X58: - | Y58: - | Z58: - | AA58: - | AB58: - | AC58: - | AD58: - | AE58: - | AF58: - | AG58: - | AH58: - | AI58: - | AJ58: - | AK58: - | AL58: - | AM58: - | AN58: - | AO58: - | AP58: - | AQ58: - | AR58: - | AS58: - | AT58: - | AU58: - | AV58: - | AW58: - | AX58: - | AY58: - | AZ58: - | BA58: - | BB58: - | BC58: - | BD58: - | BE58: - | BF58: - | BG58: - | BH58: - | BI58: - | BJ58: - | BK58: - | BL58: - | BM58: - | BN58: - | BO58: - | BP58: - | BQ58: - | BR58: - | BS58: - | BT58: - | BU58: - | BV58: - | BW58: - | BX58: - | BY58: - | BZ58: - | CA58: - | CB58: - | CC58: - | CD58: - | CE58: - | CF58: - | CG58: - | CH58: - | CI58: - | CJ58: - | CK58: - | CL58: - | CM58: - | CN58: - | CO58: - | CP58: - | CQ58: - | CR58: - | CS58: - | CT58: - | CU58: - | CV58: - | CW58: - | CX58: - | CY58: - | CZ58: - | DA58: - | DB58: - | DC58: 0 | DD58: 0 | DE58: 0 | DF58: 0 | DG58: 9.06 | DH58: 0 | DI58: 0 | DJ58: 0 | DK58: 0 | DL58: 3.18 | DM58: 6.99 | DN58: 7.25 | DO58: 3.45 | DP58: 3.14 | DQ58: 3.48 | DR58: 4.13 | DS58: 4.32 | DT58: 3.91 | DU58: 3.49 | DV58: 3.18 | DW58: 3.26 | DX58: 3.69 | DY58: 3.89 | DZ58: 3.84 | EA58: 3.82 | EB58: 5.46 | EC58: 7.03 | ED58: 7.38
A59: Days Payable | B59: 215.6 | C59: 114.91 | D59: 12.75 | E59: 7.01 | F59: 4 | G59: 9.18 | H59: 20.91 | I59: 25.67 | J59: 27.13 | K59: 71.74 | L59: 61.76 | M59: 80.54 | O59: - | P59: - | Q59: - | R59: - | S59: - | T59: - | U59: - | V59: - | W59: - | X59: - | Y59: - | Z59: - | AA59: - | AB59: - | AC59: - | AD59: - | AE59: - | AF59: - | AG59: - | AH59: - | AI59: - | AJ59: - | AK59: - | AL59: - | AM59: - | AN59: - | AO59: - | AP59: - | AQ59: - | AR59: - | AS59: - | AT59: - | AU59: - | AV59: - | AW59: - | AX59: - | AY59: - | AZ59: - | BA59: - | BB59: - | BC59: - | BD59: - | BE59: - | BF59: - | BG59: - | BH59: - | BI59: - | BJ59: - | BK59: - | BL59: - | BM59: - | BN59: - | BO59: - | BP59: - | BQ59: - | BR59: - | BS59: - | BT59: - | BU59: - | BV59: - | BW59: - | BX59: - | BY59: - | BZ59: - | CA59: - | CB59: - | CC59: - | CD59: - | CE59: - | CF59: - | CG59: - | CH59: - | CI59: - | CJ59: - | CK59: - | CL59: - | CM59: - | CN59: - | CO59: - | CP59: - | CQ59: - | CR59: - | CS59: - | CT59: - | CU59: - | CV59: - | CW59: - | CX59: - | CY59: - | CZ59: - | DA59: - | DB59: - | DC59: 0 | DD59: 0 | DE59: 0 | DF59: 0 | DG59: 250.08 | DH59: 215.48 | DI59: 200.52 | DJ59: 204.75 | DK59: 206.66 | DL59: 97.63 | DM59: 105.7 | DN59: 103.27 | DO59: 8.32 | DP59: 4.48 | DQ59: 5.49 | DR59: 6.71 | DS59: 6.7 | DT59: 10.91 | DU59: 14.45 | DV59: 23.04 | DW59: 24.7 | DX59: 23.39 | DY59: 25.09 | DZ59: 27.68 | EA59: 26.48 | EB59: 71.11 | EC59: 122.15 | ED59: 60.53
A60: Days Inventory | B60: 0 | C60: 0 | D60: 0 | E60: 0 | F60: 0 | G60: 501.53 | H60: 493.98 | I60: 0 | J60: 0 | K60: 0 | L60: 0 | M60: 0 | O60: - | P60: - | Q60: - | R60: - | S60: - | T60: - | U60: - | V60: - | W60: - | X60: - | Y60: - | Z60: - | AA60: - | AB60: - | AC60: - | AD60: - | AE60: - | AF60: - | AG60: - | AH60: - | AI60: - | AJ60: - | AK60: - | AL60: - | AM60: - | AN60: - | AO60: - | AP60: - | AQ60: - | AR60: - | AS60: - | AT60: - | AU60: - | AV60: - | AW60: - | AX60: - | AY60: - | AZ60: - | BA60: - | BB60: - | BC60: - | BD60: - | BE60: - | BF60: - | BG60: - | BH60: - | BI60: - | BJ60: - | BK60: - | BL60: - | BM60: - | BN60: - | BO60: - | BP60: - | BQ60: - | BR60: - | BS60: - | BT60: - | BU60: - | BV60: - | BW60: - | BX60: - | BY60: - | BZ60: - | CA60: - | CB60: - | CC60: - | CD60: - | CE60: - | CF60: - | CG60: - | CH60: - | CI60: - | CJ60: - | CK60: - | CL60: - | CM60: - | CN60: - | CO60: - | CP60: - | CQ60: - | CR60: - | CS60: - | CT60: - | CU60: - | CV60: - | CW60: - | CX60: - | CY60: - | CZ60: - | DA60: - | DB60: - | DC60: 0 | DD60: 0 | DE60: 0 | DF60: 0 | DG60: 0 | DH60: 0 | DI60: 0 | DJ60: 0 | DK60: 0 | DL60: 0 | DM60: 0 | DN60: 0 | DO60: 0 | DP60: 0 | DQ60: 279.59 | DR60: 290.7 | DS60: 220.71 | DT60: 350.97 | DU60: 478.13 | DV60: 0 | DW60: 0 | DX60: 0 | DY60: 0 | DZ60: 0 | EA60: 0 | EB60: 0 | EC60: 0 | ED60: 0
A61: Cash Conversion Cycle | B61: -215.6 | C61: -111.65 | D61: -9.27 | E61: -3.54 | F61: -0.22 | G61: 496.25 | H61: 476.42 | I61: -22.32 | J61: -23.18 | K61: -66.27 | L61: -53.9 | M61: -73.11 | O61: - | P61: - | Q61: - | R61: - | S61: - | T61: - | U61: - | V61: - | W61: - | X61: - | Y61: - | Z61: - | AA61: - | AB61: - | AC61: - | AD61: - | AE61: - | AF61: - | AG61: - | AH61: - | AI61: - | AJ61: - | AK61: - | AL61: - | AM61: - | AN61: - | AO61: - | AP61: - | AQ61: - | AR61: - | AS61: - | AT61: - | AU61: - | AV61: - | AW61: - | AX61: - | AY61: - | AZ61: - | BA61: - | BB61: - | BC61: - | BD61: - | BE61: - | BF61: - | BG61: - | BH61: - | BI61: - | BJ61: - | BK61: - | BL61: - | BM61: - | BN61: - | BO61: - | BP61: - | BQ61: - | BR61: - | BS61: - | BT61: - | BU61: - | BV61: - | BW61: - | BX61: - | BY61: - | BZ61: - | CA61: - | CB61: - | CC61: - | CD61: - | CE61: - | CF61: - | CG61: - | CH61: - | CI61: - | CJ61: - | CK61: - | CL61: - | CM61: - | CN61: - | CO61: - | CP61: - | CQ61: - | CR61: - | CS61: - | CT61: - | CU61: - | CV61: - | CW61: - | CX61: - | CY61: - | CZ61: - | DA61: - | DB61: - | DC61: 0 | DD61: 0 | DE61: 0 | DF61: 0 | DG61: -241.02 | DH61: -215.48 | DI61: -200.52 | DJ61: -204.75 | DK61: -206.66 | DL61: -94.45 | DM61: -98.71 | DN61: -96.02 | DO61: -4.87 | DP61: -1.34 | DQ61: 277.58 | DR61: 288.12 | DS61: 218.33 | DT61: 343.97 | DU61: 467.17 | DV61: -19.86 | DW61: -21.44 | DX61: -19.7 | DY61: -21.2 | DZ61: -23.84 | EA61: -22.66 | EB61: -65.65 | EC61: -115.12 | ED61: -53.15
A62: Inventory Turnover | B62: 0 | C62: 0 | D62: 0 | E62: 0 | F62: 0 | G62: 0.73 | H62: 0.74 | I62: 0 | J62: 0 | K62: 0 | L62: 0 | O62: - | P62: - | Q62: - | R62: - | S62: - | T62: - | U62: - | V62: - | W62: - | X62: - | Y62: - | Z62: - | AA62: - | AB62: - | AC62: - | AD62: - | AE62: - | AF62: - | AG62: - | AH62: - | AI62: - | AJ62: - | AK62: - | AL62: - | AM62: - | AN62: - | AO62: - | AP62: - | AQ62: - | AR62: - | AS62: - | AT62: - | AU62: - | AV62: - | AW62: - | AX62: - | AY62: - | AZ62: - | BA62: - | BB62: - | BC62: - | BD62: - | BE62: - | BF62: - | BG62: - | BH62: - | BI62: - | BJ62: - | BK62: - | BL62: - | BM62: - | BN62: - | BO62: - | BP62: - | BQ62: - | BR62: - | BS62: - | BT62: - | BU62: - | BV62: - | BW62: - | BX62: - | BY62: - | BZ62: - | CA62: - | CB62: - | CC62: - | CD62: - | CE62: - | CF62: - | CG62: - | CH62: - | CI62: - | CJ62: - | CK62: - | CL62: - | CM62: - | CN62: - | CO62: - | CP62: - | CQ62: - | CR62: - | CS62: - | CT62: - | CU62: - | CV62: - | CW62: - | CX62: - | CY62: - | CZ62: - | DA62: - | DB62: - | DC62: 0 | DD62: 0 | DE62: 0 | DF62: 0 | DG62: 0 | DH62: 0 | DI62: 0 | DJ62: 0 | DK62: 0 | DL62: 0 | DM62: 0 | DN62: 0 | DO62: 0 | DP62: 0 | DQ62: 0.65 | DR62: 0.63 | DS62: 0.83 | DT62: 0.52 | DU62: 0.38 | DV62: 0 | DW62: 0 | DX62: 0 | DY62: 0 | DZ62: 0 | EA62: 0 | EB62: 0 | EC62: 0 | ED62: 0
...

Sheet Ratios
E1: Indicador | F1: 2011 | G1: 2012 | H1: 2013 | I1: 2014 | J1: 2015 | K1: 2016 | L1: 2017 | M1: 2018 | N1: 2019 | O1: 2020 | P1: 2021 | Q1: TTM | R1: Grafica | S1: Promedio
B2: Amortización | C2: amortización/utilidad bruta Amortization/ gross profit | D2: * Una empresa con menor a 10% es bueno * Más del 20% indica mucha competencia en el sector | F2: =HKSE_00823!B157/HKSE_00823!B69 -> 0.006586169 | G2: =HKSE_00823!C157/HKSE_00823!C69 -> 0.0059737157 | H2: =HKSE_00823!D157/HKSE_00823!D69 -> 0.0058492201 | I2: =HKSE_00823!E157/HKSE_00823!E69 -> 0.0038446751 | J2: =HKSE_00823!F157/HKSE_00823!F69 -> 0.0040571529 | K2: =HKSE_00823!G157/HKSE_00823!G69 -> 0.0033778597 | L2: =HKSE_00823!H157/HKSE_00823!H69 -> 0.0038604518 | M2: =HKSE_00823!I157/HKSE_00823!I69 -> 0.0026099439 | ... Q2: =HKSE_00823!M157/HKSE_00823!M69 -> 0 | S2: =AVERAGE(F2:P2) -> 0.0053809888
B3: Beneficio neto | C3: Beneficio neto/ingresos Net income / sales | D3: * Algo mayor a 20% indica una ventaja * Algo menor a 10% puede indicar mucha competencia * empresas que generen entre un 10 al 20% son buenas * los bancos suelen tener porcentajes más altos | F3: =HKSE_00823!B85/HKSE_00823!B67 -> 2.8544741 | G3: =HKSE_00823!C85/HKSE_00823!C67 -> 1.6186784 | H3: =HKSE_00823!D85/HKSE_00823!D67 -> 3.2373194 | I3: =HKSE_00823!E85/HKSE_00823!E67 -> 2.4185884 | J3: =HKSE_00823!F85/HKSE_00823!F67 -> 3.5258319 | K3: =HKSE_00823!G85/HKSE_00823!G67 -> 1.8644165 | L3: =HKSE_00823!H85/HKSE_00823!H67 -> 1.9136683 | M3: =HKSE_00823!I85/HKSE_00823!I67 -> 4.7651402 | ... Q3: =HKSE_00823!M85/HKSE_00823!M67 -> 0.11029412 | S3: =AVERAGE(F3:P3) -> 2.066938
B4: Margen bruto (gross profit) | C4: Utilidad bruta/ventas Gross profit/ sales | D4: * Un porcentaje mayor a 40% indica cierta ventaja * Porcentajes menores a 40% en un sector significa demasiada competencia y algo menor al 20% en una industria indica dificultad de crear ventaja | F4: =HKSE_00823!B69/HKSE_00823!B67 -> 0.68073977 | G4: =HKSE_00823!C69/HKSE_00823!C67 -> 0.70549562 | H4: =HKSE_00823!D69/HKSE_00823!D67 -> 0.70949892 | I4: =HKSE_00823!E69/HKSE_00823!E67 -> 0.72704403 | J4: =HKSE_00823!F69/HKSE_00823!F67 -> 0.73404118 | K4: =HKSE_00823!G69/HKSE_00823!G67 -> 0.74519451 | L4: =HKSE_00823!H69/HKSE_00823!H67 -> 0.75569962 | M4: =HKSE_00823!I69/HKSE_00823!I67 -> 0.76454155 | ... Q4: =HKSE_00823!M69/HKSE_00823!M67 -> 0.76675354 | S4: =AVERAGE(F4:P4) -> 0.7383644
B5: Margen operativo | C5: Operating profit/sales | D5: Se busca tendencia alcista | F5: =HKSE_00823!B74/HKSE_00823!B67 -> 0.64786101 | G5: =HKSE_00823!C74/HKSE_00823!C67 -> 0.66014835 | H5: =HKSE_00823!D74/HKSE_00823!D67 -> 0.67522287 | I5: =HKSE_00823!E74/HKSE_00823!E67 -> 0.69601677 | J5: =HKSE_00823!F74/HKSE_00823!F67 -> 0.67745695 | K5: =HKSE_00823!G74/HKSE_00823!G67 -> 0.70308924 | L5: =HKSE_00823!H74/HKSE_00823!H67 -> 0.71874662 | M5: =HKSE_00823!I74/HKSE_00823!I67 -> 0.72293724 | ... Q5: =HKSE_00823!M74/HKSE_00823!M67 -> 0.72691735 | S5: =AVERAGE(F5:P5) -> 0.69838474
B6: EPS without NRI | C6: Beneficio neto + discontinued operations/ # acciones Net income+discontinued operations / # shares | D6: Se busca tendencia a la alza en los ultimos 5 0 10 años | F6: =HKSE_00823!B25 -> 6.89 | G6: =HKSE_00823!C25 -> 4.27 | H6: =HKSE_00823!D25 -> 9.23 | I6: =HKSE_00823!E25 -> 7.51 | J6: =HKSE_00823!F25 -> 11.82 | K6: =HKSE_00823!G25 -> 7.19 | L6: =HKSE_00823!H25 -> 7.93 | M6: =HKSE_00823!I25 -> 21.69 | ... Q6: =HKSE_00823!M25 -> 0.57 | S6: =AVERAGE(F6:P6) -> 7.1354545
B7: Revenue per share | D7: Se busca tendencia alcista | F7: =HKSE_00823!B21 -> 2.414 | G7: =HKSE_00823!C21 -> 2.637 | H7: =HKSE_00823!D21 -> 2.852 | I7: =HKSE_00823!E21 -> 3.104 | J7: =HKSE_00823!F21 -> 3.353 | K7: =HKSE_00823!G21 -> 3.851 | L7: =HKSE_00823!H21 -> 4.142 | M7: =HKSE_00823!I21 -> 4.553 | ... Q7: =HKSE_00823!M21 -> 5.198 | S7: =AVERAGE(F7:P7) -> 3.8124545
B8: Shares outstanding | F8: =HKSE_00823!B89 -> 2217.453 | G8: =HKSE_00823!C89 -> 2249.456 | H8: =HKSE_00823!D89 -> 2281.11 | I8: =HKSE_00823!E89 -> 2305.32 | J8: =HKSE_00823!F89 -> 2303.647 | K8: =HKSE_00823!G89 -> 2269.434 | L8: =HKSE_00823!H89 -> 2234.29 | M8: =HKSE_00823!I89 -> 2201.586 | ... Q8: =HKSE_00823!M89 -> 2072.435 | S8: =AVERAGE(F8:P8) -> 2213.7959
B9: Net income | F9: =HKSE_00823!B85 -> 15280 | G9: =HKSE_00823!C85 -> 9602 | H9: =HKSE_00823!D85 -> 21062 | I9: =HKSE_00823!E85 -> 17305 | J9: =HKSE_00823!F85 -> 27230 | K9: =HKSE_00823!G85 -> 16295 | L9: =HKSE_00823!H85 -> 17711 | M9: =HKSE_00823!I85 -> 47761 | ... Q9: =HKSE_00823!M85 -> 1185 | S9: =AVERAGE(F9:P9) -> 16058
B10: Crecimiento del Net Income (Crecimiento de la empresa) | G10: =(G9-F9)/F9 -> -0.37159686 | H10: =(H9-G9)/G9 -> 1.1935014 | I10: =(I9-H9)/H9 -> -0.17837812 | J10: =(J9-I9)/I9 -> 0.57353366 | K10: =(K9-J9)/J9 -> -0.40157914 | L10: =(L9-K9)/K9 -> 0.086897821 | M10: =(M9-L9)/L9 -> 1.6966857 | N10: =(N9-M9)/M9 -> -0.57435983 | O10: =(O9-N9)/N9 -> -1.8422451 | P10: =-(P9-O9)/O9 -> 1.0692092 | Q10: =(Q9-P9)/P9 -> 0 | S10: =AVERAGE(F10:P10) -> 0.12516687
B11: Sales | F11: =HKSE_00823!B67 -> 5353 | G11: =HKSE_00823!C67 -> 5932 | H11: =HKSE_00823!D67 -> 6506 | I11: =HKSE_00823!E67 -> 7155 | J11: =HKSE_00823!F67 -> 7723 | K11: =HKSE_00823!G67 -> 8740 | L11: =HKSE_00823!H67 -> 9255 | M11: =HKSE_00823!I67 -> 10023 | ... Q11: =HKSE_00823!M67 -> 10744 | S11: =AVERAGE(F11:P11) -> 8380.5455
B12: Crecimiento de Sales | G12: =(G11-F11)/F11 -> 0.10816365 | H12: =(H11-G11)/G11 -> 0.096763318 | I12: =(I11-H11)/H11 -> 0.099754073 | J12: =(J11-I11)/I11 -> 0.079385045 | K12: =(K11-J11)/J11 -> 0.13168458 | L12: =(L11-K11)/K11 -> 0.058924485 | M12: =(M11-L11)/L11 -> 0.082982172 | N12: =(N11-M11)/M11 -> 0.0013967874 | ... Q12: =(Q11-P11)/P11 -> 0 | S12: =AVERAGE(F12:P12) -> 0.072932889
B13: Cost of Revenue | F13: =HKSE_00823!B68 -> 1709 | G13: =HKSE_00823!C68 -> 1747 | H13: =HKSE_00823!D68 -> 1890 | I13: =HKSE_00823!E68 -> 1953 | J13: =HKSE_00823!F68 -> 2054 | K13: =HKSE_00823!G68 -> 2227 | L13: =HKSE_00823!H68 -> 2261 | M13: =HKSE_00823!I68 -> 2360 | ... Q13: =HKSE_00823!M68 -> 2506 | S13: =AVERAGE(F13:P13) -> 2141.1818
B14: Crecimiento de COR | G14: =(G13-F13)/F13 -> 0.022235225 | H14: =(H13-G13)/G13 -> 0.081854608 | I14: =(I13-H13)/H13 -> 0.033333333 | J14: =(J13-I13)/I13 -> 0.05171531 | K14: =(K13-J13)/J13 -> 0.084225901 | L14: =(L13-K13)/K13 -> 0.015267176 | M14: =(M13-L13)/L13 -> 0.043785935 | N14: =(N13-M13)/M13 -> -0.0050847458 | ... Q14: =(Q13-P13)/P13 -> 0 | S14: =AVERAGE(F14:P14) -> 0.039441946
B15: Inventory | F15: =HKSE_00823!B107 -> 0 | G15: =HKSE_00823!C107 -> 0 | H15: =HKSE_00823!D107 -> 0 | I15: =HKSE_00823!E107 -> 0 | J15: =HKSE_00823!F107 -> 0 | K15: =HKSE_00823!G107 -> 3060 | L15: =HKSE_00823!H107 -> 0 | M15: =HKSE_00823!I107 -> 0 | ... Q15: =HKSE_00823!M107 -> 0 | S15: =AVERAGE(F15:P15) -> 278.18182
B16: Crecimiento de inventory | F16: 0 | G16: 0 | H16: 0 | I16: 0 | J16: 0 | K16: 0 | L16: 0 | M16: 0 | N16: 0 | O16: 0 | P16: 0 | Q16: 0 | S16: =AVERAGE(F16:P16) -> 0
B17: Cuentas por cobrar/ventas | C17: Cuentas por cobrar/ventas | D17: Entre menor sea el rango mejor, ya que indica una ventaja competitiva | F17: =HKSE_00823!B97/HKSE_00823!B67 -> 0 | G17: =HKSE_00823!C97/HKSE_00823!C67 -> 0.008934592 | H17: =HKSE_00823!D97/HKSE_00823!D67 -> 0.010913003 | I17: =HKSE_00823!E97/HKSE_00823!E67 -> 0.0090845563 | J17: =HKSE_00823!F97/HKSE_00823!F67 -> 0.012300919 | K17: =HKSE_00823!G97/HKSE_00823!G67 -> 0.010526316 | L17: =HKSE_00823!H97/HKSE_00823!H67 -> 0.0084278768 | M17: =HKSE_00823!I97/HKSE_00823!I67 -> 0.010575676 | ... Q17: =HKSE_00823!M97/HKSE_00823!M67 -> 0.023548027 | S17: =AVERAGE(F17:P17) -> 0.011360296
B18: Divident payout ratio | C18: Dividend earnings per share/ earnings per share Dividendos por accion/ beneficios por accion | D18: *Buscar empresas que tenga un ratio de entre 20 y 60% | F18: =F19/F6 -> 0.14614224 | G18: =G19/G6 -> 0.28266979 | H18: =H19/H6 -> 0.14895991 | I18: =I19/I6 -> 0.20719041 | J18: =J19/J6 -> 0.14818105 | K18: =K19/K6 -> 0.26741307 | L18: =L19/L6 -> 0.27609079 | M18: =M19/M6 -> 0.10980175 | ... Q18: =Q19/Q6 -> 5.0415789 | S18: =AVERAGE(F18:P18) -> 0.59578674
B19: Dividends per sahre | F19: =HKSE_00823!B31 -> 1.00692 | G19: =HKSE_00823!C31 -> 1.207 | H19: =HKSE_00823!D31 -> 1.3749 | I19: =HKSE_00823!E31 -> 1.556 | J19: =HKSE_00823!F31 -> 1.7515 | K19: =HKSE_00823!G31 -> 1.9227 | L19: =HKSE_00823!H31 -> 2.1894 | M19: =HKSE_00823!I31 -> 2.3816 | ... Q19: =HKSE_00823!M31 -> 2.8737 | S19: =AVERAGE(F19:P19) -> 1.9702655
B20: Free Cash flow | C20: Cash flow from operating activities + Purchase of PP&E | F20: =HKSE_00823!B193 -> 3349 | G20: =HKSE_00823!C193 -> 3743 | H20: =HKSE_00823!D193 -> 4174 | I20: =HKSE_00823!E193 -> 4641 | J20: =HKSE_00823!F193 -> 4828 | K20: =HKSE_00823!G193 -> 5664 | L20: =HKSE_00823!H193 -> 6038 | M20: =HKSE_00823!I193 -> 6446 | ... Q20: =HKSE_00823!M193 -> 7041 | S20: =AVERAGE(F20:P20) -> 5256.5455
B21: Flujo de caja libre | C21: (Free Cash Flow) / ventas | D21: Si el porcentaje da algo en torno al 50% puede indicar un foso económico | F21: =F20/F11 -> 0.62563049 | G21: =G20/G11 -> 0.63098449 | H21: =H20/H11 -> 0.64156164 | I21: =I20/I11 -> 0.64863732 | J21: =J20/J11 -> 0.62514567 | K21: =K20/K11 -> 0.64805492 | L21: =L20/L11 -> 0.65240411 | M21: =M20/M11 -> 0.64312082 | ... Q21: =Q20/Q11 -> 0.65534252 | S21: =AVERAGE(F21:P21) -> 0.62893415
B22: Free cash flow per share | C22: free cash flow / Shares outstandig | D22: Se busca una tendencia alcista | F22: =F20/F8 -> 1.5102913 | G22: =G20/G8 -> 1.6639579 | H22: =H20/H8 -> 1.8298109 | I22: =I20/I8 -> 2.0131695 | J22: =J20/J8 -> 2.0958072 | K22: =K20/K8 -> 2.4957765 | L22: =L20/L8 -> 2.7024245 | M22: =M20/M8 -> 2.9278893 | ... Q22: =Q20/Q8 -> 3.3974528 | S22: =AVERAGE(F22:P22) -> 2.3892546
B23: Free cash flow to debt | C23: Free cash flow/total debt | D23: Entre más cerca este de pagarla mejor | F23: =F20/(HKSE_00823!B139+HKSE_00823!B131) -> 0.32263969 | G23: =G20/(HKSE_00823!C139+HKSE_00823!C131) -> 0.29718142 | H23: =H20/(HKSE_00823!D139+HKSE_00823!D131) -> 0.30838567 | I23: =I20/(HKSE_00823!E139+HKSE_00823!E131) -> 0.37056851 | J23: =J20/(HKSE_00823!F139+HKSE_00823!F131) -> 0.28283538 | K23: =K20/(HKSE_00823!G139+HKSE_00823!G131) -> 0.21036993 | L23: =L20/(HKSE_00823!H139+HKSE_00823!H131) -> 0.21958759 | M23: =M20/(HKSE_00823!I139+HKSE_00823!I131) -> 0.2499903 | ... Q23: =Q20/(HKSE_00823!M139+HKSE_00823!M131) -> 0.18223936 | S23: =AVERAGE(F23:P23) -> 0.2600629
B24: Free cash flow to current debt | C24: Free cash flow / current debt and capital lease obligation | D24: Entre más cerca este de pagarla mejor | F24: =F20/HKSE_00823!B131 -> 1.2890685 | G24: No deuda | H24: =H20/HKSE_00823!D131 -> 2.4466589 | I24: =I20/HKSE_00823!E131 -> 1.6428319 | J24: =J20/HKSE_00823!F131 -> 2.4886598 | K24: =K20/HKSE_00823!G131 -> 5.9061522 | L24: =L20/HKSE_00823!H131 -> 20.126667 | M24: =M20/HKSE_00823!I131 -> 2.4897644 | N24: No deuda | O24: No deuda | P24: No deuda | Q24: No deuda | S24: =AVERAGE(F24:P24) -> 5.1985432
B25: Deuda a largo plazo | C25: net income/ long term debt | D25: Cuando una compañía tiene 10 años o más con poca o ninguna indica una ventaja competitiva *La empresa debera contar con beneficiones netos anuales, para ahcer frente a su deuda a largo plazo por los proximos dos o tres años | F25: =HKSE_00823!B85/HKSE_00823!B139 -> 1.9635055 | G25: =HKSE_00823!C85/HKSE_00823!C139 -> 0.76236602 | H25: =HKSE_00823!D85/HKSE_00823!D139 -> 1.7805394 | I25: =HKSE_00823!E85/HKSE_00823!E139 -> 1.7842046 | J25: =HKSE_00823!F85/HKSE_00823!F139 -> 1.7997356 | K25: =HKSE_00823!G85/HKSE_00823!G139 -> 0.62757558 | L25: =HKSE_00823!H85/HKSE_00823!H139 -> 0.65121153 | M25: =HKSE_00823!I85/HKSE_00823!I139 -> 2.0590188 | ... Q25: =HKSE_00823!M85/HKSE_00823!M139 -> 0.030670877 | S25: =AVERAGE(F25:P25) -> 1.0730359
B26: Pasivo total/fondos propios | C26: pasivo total / fondos propios + acciones en tesoro total liabilities/ shareholders equity + treasury stock | D26: Si algo es menor a 1 es mejor * Para las financiera un relación menor a .80 es una ventaja competitiva | F26: =HKSE_00823!B144/HKSE_00823!B154 -> 0.2506412 | G26: =HKSE_00823!C144/HKSE_00823!C154 -> 0.26285168 | H26: =HKSE_00823!D144/HKSE_00823!D154 -> 0.21779231 | I26: =HKSE_00823!E144/HKSE_00823!E154 -> 0.17763178 | J26: =HKSE_00823!F144/HKSE_00823!F154 -> 0.211996 | K26: =HKSE_00823!G144/HKSE_00823!G154 -> 0.28256997 | L26: =HKSE_00823!H144/HKSE_00823!H154 -> 0.27035243 | M26: =HKSE_00823!I144/HKSE_00823!I154 -> 0.2085018 | ... Q26: =HKSE_00823!M144/HKSE_00823!M154 -> 0.32258512 | S26: =AVERAGE(F26:P26) -> 0.24547729
B27: Ratio de solvencia | C27: Activos corrientes/pasivos corrientes current assets / current liabilities | D27: *En teoría algo mayor a 1 indica solvencia, pero existen empresas con algo menor a 1 que debido a su rentabilidad pueden cubrir el pasivo *Algo mayor a 1.5 puede ser muy bueno *evitar aquellas menores a .5 | F27: =HKSE_00823!B109/HKSE_00823!B136 -> 0.22831549 | G27: =HKSE_00823!C109/HKSE_00823!C136 -> 0.87082405 | H27: =HKSE_00823!D109/HKSE_00823!D136 -> 0.83015722 | I27: =HKSE_00823!E109/HKSE_00823!E136 -> 0.55983369 | J27: =HKSE_00823!F109/HKSE_00823!F136 -> 0.78422131 | K27: =HKSE_00823!G109/HKSE_00823!G136 -> 0.91725553 | L27: =HKSE_00823!H109/HKSE_00823!H136 -> 0.31265447 | M27: =HKSE_00823!I109/HKSE_00823!I136 -> 1.7303806 | ... Q27: =HKSE_00823!M109/HKSE_00823!M136 -> 0.97006931 | S27: =AVERAGE(F27:P27) -> 1.0526949
B28: Deuda/ capital | C28: Long term debt/equity | D28: Se busca un balance de 75% capital, 25% deuda Se busca resultados menores a 25% | F28: =HKSE_00823!B139/HKSE_00823!B154 -> 0.14155525 | G28: =HKSE_00823!C139/HKSE_00823!C154 -> 0.20076512 | H28: =HKSE_00823!D139/HKSE_00823!D154 -> 0.14488866 | I28: =HKSE_00823!E139/HKSE_00823!E154 -> 0.1006632 | J28: =HKSE_00823!F139/HKSE_00823!F154 -> 0.12810526 | K28: =HKSE_00823!G139/HKSE_00823!G154 -> 0.20374134 | L28: =HKSE_00823!H139/HKSE_00823!H154 -> 0.19637248 | M28: =HKSE_00823!I139/HKSE_00823!I154 -> 0.12953738 | ... Q28: =HKSE_00823!M139/HKSE_00823!M154 -> 0.24346379 | S28: =AVERAGE(F28:P28) -> 0.16664397
B29: Gasto financiero | C29: intereses a cargo - intereses ganados/beneficio de explotacion net interest income(expenses)/operating income | D29: * Un gasto menor a 15% indica una ventaja * En el area financiera un porcentaje bajo puede ser un 30% *En cualquier industria la empresa con la proporción más baja tiene la ventaja *si es positivo es aun mejor | F29: =ABS(HKSE_00823!B76/HKSE_00823!B74) -> 0.14446367 | G29: =ABS(HKSE_00823!C76/HKSE_00823!C74) -> 0.064351379 | H29: =ABS(HKSE_00823!D76/HKSE_00823!D74) -> 0.075119508 | I29: =ABS(HKSE_00823!E76/HKSE_00823!E74) -> 0.064056225 | J29: =ABS(HKSE_00823!F76/HKSE_00823!F74) -> 0.065940367 | K29: =ABS(HKSE_00823!G76/HKSE_00823!G74) -> 0.065093572 | L29: =ABS(HKSE_00823!H76/HKSE_00823!H74) -> 0.054570054 | M29: =ABS(HKSE_00823!I76/HKSE_00823!I74) -> 0.062379244 | ... Q29: =ABS(HKSE_00823!M76/HKSE_00823!M74) -> 0.10793854 | S29: =AVERAGE(F29:P29) -> 0.079743015
B30: Gasto de ventas | C30: gasto administrativos/utilidad bruta administrative expenses/ gross profit | D30: * Compañias con un 30% es fantastico * Aunque hay buenas compañias que dedican de un 30 a un 80% * Empresas con mas de 100% o cercanos indica algo malo | F30: =HKSE_00823!B70/HKSE_00823!B69 -> 0.048298573 | G30: =HKSE_00823!C70/HKSE_00823!C69 -> 0.06427718 | H30: =HKSE_00823!D70/HKSE_00823!D69 -> 0.048310225 | I30: =HKSE_00823!E70/HKSE_00823!E69 -> 0.042675894 | J30: =HKSE_00823!F70/HKSE_00823!F69 -> 0.077085906 | K30: =HKSE_00823!G70/HKSE_00823!G69 -> 0.05650238 | L30: =HKSE_00823!H70/HKSE_00823!H69 -> 0.048899056 | M30: =HKSE_00823!I70/HKSE_00823!I69 -> 0.05441733 | ... Q30: =HKSE_00823!M70/HKSE_00823!M69 -> 0.051954358 | S30: =AVERAGE(F30:P30) -> 0.054154711
B31: Gastos de capital | C31: Gastos de capital / beneficios netos totales CAPEX(Payments for adquisition on PP&E) / net income | D31: Una compañía que utilice menos del 50% de sus beneficios netos para el gasto de capital, indica una ventaja competitiva *Pero si usa menos del 25% indica una posible ventaja competitiva duradera | F31: =ABS(HKSE_00823!B192/HKSE_00823!B85) -> 0.0010471204 | G31: =ABS(HKSE_00823!C192/HKSE_00823!C85) -> 0.0028119142 | H31: =ABS(HKSE_00823!D192/HKSE_00823!D85) -> 0.0011869718 | I31: =ABS(HKSE_00823!E192/HKSE_00823!E85) -> 0.0010401618 | J31: =ABS(HKSE_00823!F192/HKSE_00823!F85) -> 0.00091810503 | K31: =ABS(HKSE_00823!G192/HKSE_00823!G85) -> 0.0011046333 | L31: =ABS(HKSE_00823!H192/HKSE_00823!H85) -> 0.0022020213 | M31: =ABS(HKSE_00823!I192/HKSE_00823!I85) -> 0.00081656582 | ... Q31: =ABS(HKSE_00823!M192/HKSE_00823!M85) -> 0.031223629 | S31: =AVERAGE(F31:P31) -> 0.0071646575
B32: Inventory to current assets | C32: inventories/current asset | D32: Buscar compañias con un rango menor al 40% y evitar empresas con algo mayor al 60% | F32: =HKSE_00823!B107/HKSE_00823!B109 -> 0 | G32: =HKSE_00823!C107/HKSE_00823!C109 -> 0 | H32: =HKSE_00823!D107/HKSE_00823!D109 -> 0 | I32: =HKSE_00823!E107/HKSE_00823!E109 -> 0 | J32: =HKSE_00823!F107/HKSE_00823!F109 -> 0 | K32: =HKSE_00823!G107/HKSE_00823!G109 -> 0.76043738 | L32: =HKSE_00823!H107/HKSE_00823!H109 -> 0 | M32: =HKSE_00823!I107/HKSE_00823!I109 -> 0 | ... Q32: =HKSE_00823!M107/HKSE_00823!M109 -> 0 | S32: =AVERAGE(F32:P32) -> 0.069130671
B33: Net trading cycle | C33: (Rotación de cuentas por cobrar + Rotación de inventarios - Rotación de cuentas por pagar)} CXC = ((trade/receivables 2020+AR 2019)/2)/sales*360 CXP= ((Accounts payable 2019 + AP 2020)/2)/COGS*360 ROT. INV = ((Inventory 2019+INV 2020)/2)/COGS*360 | D33: *Entre menor sea, mejor | F33: =HKSE_00823!B61 -> -215.6 | G33: =HKSE_00823!C61 -> -111.65 | H33: =HKSE_00823!D61 -> -9.27 | I33: =HKSE_00823!E61 -> -3.54 | J33: =HKSE_00823!F61 -> -0.22 | K33: =HKSE_00823!G61 -> 496.25 | L33: =HKSE_00823!H61 -> 476.42 | M33: =HKSE_00823!I61 -> -22.32 | ... Q33: =HKSE_00823!M61 -> -73.11 | S33: =AVERAGE(F33:P33) -> 42.429091
B34: PEGY Ratio | C34: P/E ratio/ EPS growth rate (cuanto crecera en los siguientes 5 años, según yahoo finance o finviz, agarrar el menor) + dividend Yield | D34: Es mas efectivo que el PEG, debido a que el PEG ratio no tiene en cuenta el dividendo, lo que vuelve más cara a las empresas que si pagan dividendos *No es efectivo para empresas que pagan más de un 8% de dividendo Buscar que sea menor a 1 | P34: =Q35/(8.46+4.24) -> 9.4141732 | S34: =AVERAGE(F34:P34) -> 9.4141732
B35: PER | C35: Precio*acciones en circulación / beneficio neto Price* shares outstandings / net income | D35: * No invertir en acciones con PER promedio mayor a 15 * PER menor a 9 es bueno y más una acción dentro de un indice *una acción se puede vender cuando ofrecer PER mayores a 40, sobre todo en empresas grandes *Cuando una empresa crece al mismo risto pero su PER promedio baja puede ser interesante | F35: =HKSE_00823!B195 -> 3.53 | G35: =HKSE_00823!C195 -> 6.77 | H35: =HKSE_00823!D195 -> 4.58 | I35: =HKSE_00823!E195 -> 5.08 | J35: =HKSE_00823!F195 -> 4.04 | K35: =HKSE_00823!G195 -> 6.4 | L35: =HKSE_00823!H195 -> 6.87 | M35: =HKSE_00823!I195 -> 3.09 | ... Q35: =HKSE_00823!M195 -> 119.56 | S35: =AVERAGE(F35:P35) -> 17.417
